<!-- 47.1 에러 처리의 필요성 -->

<!-- 에러가 발생하지 않는 코드를 작성하는 것은 불가능하다. 따라서 에러는 언제나 발생할 수 있다. 발생한 에러에 대해
대처하지 않고 방치하면 프로그램은 강제 종료 된다.

try...catch 문을 사용해 발생한 에러에 적절하게 대응하면 프로그램이 강제 종료되지 않고 계속해서 코드를 실행시킬 수 있다. -->

<!-- 47.2 try...catch...finally 문 -->

<!-- try...catch...finally 문을 실행하면 먼저 try 코드 블록이 실행된다. 이 때 try 코드 블록에 포함된 문 중에서 에러가
발생하면 발생한 에러는 catch 문의 err 변수에 전달되고 catch 코드 블록이 실행된다. catch 문의 err 변수는 try 코드
블록에 포함된 문 중에서 에러가 발생하면 생성되고 catch 코드 블록에서만 유효하다. finally 코드 블록은 에러 발생과
상관없이 반드시 한 번 실행된다. try...catch...finally 문으로 에러를 처리하면 프로그램이 강제 종료되지 않는다. -->